Workbook

Sheet for conversion
A1: account_no | B1: Name | C1: adjusted_gross_score | D1: slope_rating | E1: course_rating | F1: holes_completed | G1: date_played | H1: tee | I1: course | J1: tournament_name | K1: course_id | L1: tee_id | M1: whs_no
A2: 7524-03 | B2: JUNSAY, JARED JAMES | C2: 83 | D2: 134 | E2: 72.8 | F2: 18 | G2: 45888 | H2: B | I2: SOUTH | J2: ALL JUNIORS 2025 | M2: =VLOOKUP(A2,Sheet1!$A$2:$H$1628,1,FALSE) -> 7524-03
A3: 7494-06 | B3: HERMOSA, GABRIEL | C3: 87 | D3: 134 | E3: 72.8 | F3: 18 | G3: 45888 | H3: B | I3: SOUTH | J3: ALL JUNIORS 2025 | M3: =VLOOKUP(A3,Sheet1!$A$2:$H$1628,1,FALSE) -> 7494-06
A4: 8493-02 | B4: RAMOS, GAB | C4: 90 | D4: 134 | E4: 72.8 | F4: 18 | G4: 45888 | H4: B | I4: SOUTH | J4: ALL JUNIORS 2025 | M4: =VLOOKUP(A4,Sheet1!$A$2:$H$1628,1,FALSE) -> 8493-02
A5: 7783-02 | B5: BAYANI, CLARK | C5: 99 | D5: 134 | E5: 72.8 | F5: 18 | G5: 45888 | H5: B | I5: SOUTH | J5: ALL JUNIORS 2025 | M5: =VLOOKUP(A5,Sheet1!$A$2:$H$1628,1,FALSE) -> 7783-02
A6: 3243-02 | B6: CRUZ, CHRISTOPHER ANDREI | C6: 103 | D6: 134 | E6: 72.8 | F6: 18 | G6: 45888 | H6: B | I6: SOUTH | J6: ALL JUNIORS 2025 | M6: =VLOOKUP(A6,Sheet1!$A$2:$H$1628,1,FALSE) -> 3243-02
A7: 8225-03 | B7: NICOLAS, RYAN JR. | C7: 95 | D7: 134 | E7: 72.8 | F7: 18 | G7: 45888 | H7: B | I7: SOUTH | J7: ALL JUNIORS 2025 | M7: =VLOOKUP(A7,Sheet1!$A$2:$H$1628,1,FALSE) -> 8225-03
A8: 8356-02 | B8: LIMPIADA, ZIAN JAMES | C8: 96 | D8: 134 | E8: 72.8 | F8: 18 | G8: 45888 | H8: B | I8: SOUTH | J8: ALL JUNIORS 2025 | M8: =VLOOKUP(A8,Sheet1!$A$2:$H$1628,1,FALSE) -> 8356-02
A9: 3243-03 | B9: CRUZ, AIDEN CHRISTOPHER | C9: 105 | D9: 134 | E9: 72.8 | F9: 18 | G9: 45888 | H9: B | I9: SOUTH | J9: ALL JUNIORS 2025 | M9: =VLOOKUP(A9,Sheet1!$A$2:$H$1628,1,FALSE) -> 3243-03
A10: 3634-02 | B10: VEA, LIAM MARCUS | C10: 105 | D10: 134 | E10: 72.8 | F10: 18 | G10: 45888 | H10: B | I10: SOUTH | J10: ALL JUNIORS 2025 | M10: =VLOOKUP(A10,Sheet1!$A$2:$H$1628,1,FALSE) -> 3634-02
A11: 2963-02 | B11: IÑIGO, MIGUEL | C11: 116 | D11: 134 | E11: 72.8 | F11: 18 | G11: 45888 | H11: B | I11: SOUTH | J11: ALL JUNIORS 2025 | M11: =VLOOKUP(A11,Sheet1!$A$2:$H$1628,1,FALSE) -> 2963-02
A12: 2606-04 | B12: MANHIT, RACE PHOENIX YATCO | C12: 80 | D12: 134 | E12: 72.8 | F12: 18 | G12: 45888 | H12: B | I12: SOUTH | J12: ALL JUNIORS 2025 | M12: =VLOOKUP(A12,Sheet1!$A$2:$H$1628,1,FALSE) -> 2606-04
A13: 3516-02 | B13: DAVID, PEIRRE XANDREI P. | C13: 81 | D13: 134 | E13: 72.8 | F13: 18 | G13: 45888 | H13: B | I13: SOUTH | J13: ALL JUNIORS 2025 | M13: =VLOOKUP(A13,Sheet1!$A$2:$H$1628,1,FALSE) -> 3516-02
A14: 3562-02 | B14: UNGCO, ROMAN FRANCESCO | C14: 81 | D14: 134 | E14: 72.8 | F14: 18 | G14: 45888 | H14: B | I14: SOUTH | J14: ALL JUNIORS 2025 | M14: =VLOOKUP(A14,Sheet1!$A$2:$H$1628,1,FALSE) -> 3562-02
A15: 3575-02 | B15: DY SUN, ADAM JOSE GAVINO B. | C15: 60 | D15: 129 | E15: 73.3 | F15: B9 | G15: 45888 | H15: R | I15: SOUTH | J15: ALL JUNIORS 2025 | M15: =VLOOKUP(A15,Sheet1!$A$2:$H$1628,1,FALSE) -> 3575-02
A16: 8203-03 | B16: CHAN, AERIN LOUISE | C16: 82 | D16: 129 | E16: 73.3 | F16: 18 | G16: 45888 | H16: R | I16: SOUTH | J16: ALL JUNIORS 2025 | M16: =VLOOKUP(A16,Sheet1!$A$2:$H$1628,1,FALSE) -> 8203-03
A17: 1757-02 | B17: MAURICIO, ALEXANDRA | C17: 83 | D17: 129 | E17: 73.3 | F17: 18 | G17: 45888 | H17: R | I17: SOUTH | J17: ALL JUNIORS 2025 | M17: =VLOOKUP(A17,Sheet1!$A$2:$H$1628,1,FALSE) -> 1757-02
A18: 7874-04 | B18: NAMOCO, MARGAUX | C18: 87 | D18: 129 | E18: 73.3 | F18: 18 | G18: 45888 | H18: R | I18: SOUTH | J18: ALL JUNIORS 2025 | M18: =VLOOKUP(A18,Sheet1!$A$2:$H$1628,1,FALSE) -> 7874-04
A19: 8411-03 | B19: EUSEBIO, JESSICA VENICE | C19: 103 | D19: 129 | E19: 73.3 | F19: 18 | G19: 45888 | H19: R | I19: SOUTH | J19: ALL JUNIORS 2025 | M19: =VLOOKUP(A19,Sheet1!$A$2:$H$1628,1,FALSE) -> 8411-03
A20: 8455-03 | B20: YAZON, MATTEO | C20: 111 | D20: 126 | E20: 70.6 | F20: 18 | G20: 45888 | H20: W | I20: SOUTH | J20: ALL JUNIORS 2025 | M20: =VLOOKUP(A20,Sheet1!$A$2:$H$1628,1,FALSE) -> 8455-03
A21: 8278-03 | B21: FERNANDO, JESUS III | C21: 112 | D21: 126 | E21: 70.6 | F21: 18 | G21: 45888 | H21: W | I21: SOUTH | J21: ALL JUNIORS 2025 | M21: =VLOOKUP(A21,Sheet1!$A$2:$H$1628,1,FALSE) -> 8278-03
A22: 8278-04 | B22: FERNANDO, JUAN JAVIER | C22: 116 | D22: 126 | E22: 70.6 | F22: 18 | G22: 45888 | H22: W | I22: SOUTH | J22: ALL JUNIORS 2025 | M22: =VLOOKUP(A22,Sheet1!$A$2:$H$1628,1,FALSE) -> 8278-04
A23: 8411-02 | B23: EUSEBIO, JENINA SYDNEY | C23: 97 | D23: 126 | E23: 70.6 | F23: 18 | G23: 45888 | H23: W | I23: SOUTH | J23: ALL JUNIORS 2025 | M23: =VLOOKUP(A23,Sheet1!$A$2:$H$1628,1,FALSE) -> 8411-02
A24: 8520-02 | B24: BAUTISTA, FRANCES CATE | C24: 97 | D24: 126 | E24: 70.6 | F24: 18 | G24: 45888 | H24: W | I24: SOUTH | J24: ALL JUNIORS 2025 | M24: =VLOOKUP(A24,Sheet1!$A$2:$H$1628,1,FALSE) -> 8520-02
A25: 7783-03 | B25: BAYANI, FELINA | C25: 112 | D25: 126 | E25: 70.6 | F25: 18 | G25: 45888 | H25: W | I25: SOUTH | J25: ALL JUNIORS 2025 | M25: =VLOOKUP(A25,Sheet1!$A$2:$H$1628,1,FALSE) -> 7783-03
A26: 2963-03 | B26: IÑIGO, MARTINA | C26: 118 | D26: 126 | E26: 70.6 | F26: 18 | G26: 45888 | H26: W | I26: SOUTH | J26: ALL JUNIORS 2025 | M26: =VLOOKUP(A26,Sheet1!$A$2:$H$1628,1,FALSE) -> 2963-03
A27: 8109-02 | B27: CAMPOSANO, INIGO | C27: 97 | D27: 126 | E27: 70.6 | F27: 18 | G27: 45888 | H27: W | I27: SOUTH | J27: ALL JUNIORS 2025 | M27: =VLOOKUP(A27,Sheet1!$A$2:$H$1628,1,FALSE) -> 8109-02
... A237: 2981-00 | B237: FAJARDO, MARLON | C237: 88 | D237: 123 | E237: 66.5 | F237: 18 | G237: 45507 | H237: W | I237: NORTH | J237: BARKADAHAN 2024 | M237: =VLOOKUP(A237,Sheet1!$A$2:$H$1628,1,FALSE) -> 2981-00
A238: 3137-00 | B238: GOROSPE, BEN | D238: 123 | E238: 66.5 | F238: 18 | G238: 45479 | H238: W | I238: NORTH | J238: BARKADAHAN 2024 | M238: =VLOOKUP(A238,Sheet1!$A$2:$H$1628,1,FALSE) -> 3137-00
A239: 1073-00 | B239: JORGE, RAOUL | C239: 74 | D239: 123 | E239: 66.5 | F239: 18 | G239: 45495 | H239: W | I239: NORTH | J239: BARKADAHAN 2024 | M239: =VLOOKUP(A239,Sheet1!$A$2:$H$1628,1,FALSE) -> 1073-00
A240: 1016-00 | B240: SAN JUAN, JOSE ERWIN | C240: 78 | D240: 123 | E240: 66.5 | F240: 18 | G240: 45508 | H240: W | I240: NORTH | J240: BARKADAHAN 2024 | M240: =VLOOKUP(A240,Sheet1!$A$2:$H$1628,1,FALSE) -> 1016-00
A241: 7971-00 | B241: SOMERA, RANDOLF | C241: 87 | D241: 123 | E241: 66.5 | F241: 18 | G241: 45465 | H241: W | I241: NORTH | J241: BARKADAHAN 2024 | M241: =VLOOKUP(A241,Sheet1!$A$2:$H$1628,1,FALSE) -> 7971-00
A242: 3330-00 | B242: SUMULONG, FRANCISCO | C242: 73 | D242: 123 | E242: 66.5 | F242: 18 | G242: 45508 | H242: W | I242: NORTH | J242: BARKADAHAN 2024 | M242: =VLOOKUP(A242,Sheet1!$A$2:$H$1628,1,FALSE) -> 3330-00
A243: 7288-00 | B243: VILALLON, VINCENT | C243: 83 | D243: 123 | E243: 66.5 | F243: 18 | G243: 45479 | H243: W | I243: NORTH | J243: BARKADAHAN 2024 | M243: =VLOOKUP(A243,Sheet1!$A$2:$H$1628,1,FALSE) -> 7288-00
A244: 7931-00 | B244: CASTILLO, GEORGE PATRICK | C244: 96 | D244: 135 | E244: 72 | F244: 18 | G244: 45487 | H244: B | I244: SOUTH | J244: BARKADAHAN 2024 | M244: =VLOOKUP(A244,Sheet1!$A$2:$H$1628,1,FALSE) -> 7931-00
A245: 8450-01 | B245: DATOC, RJ | C245: 88 | D245: 135 | E245: 72 | F245: 18 | G245: 45465 | H245: B | I245: SOUTH | J245: BARKADAHAN 2024 | M245: =VLOOKUP(A245,Sheet1!$A$2:$H$1628,1,FALSE) -> 8450-01
A246: 2606-04 | B246: MANHIT, RACE | C246: 77 | D246: 135 | E246: 72 | F246: 18 | G246: 45465 | H246: B | I246: SOUTH | J246: BARKADAHAN 2024 | M246: =VLOOKUP(A246,Sheet1!$A$2:$H$1628,1,FALSE) -> 2606-04
A247: 8149-00 | B247: MONTER0, VINCE | C247: 88 | D247: 135 | E247: 72 | F247: 18 | G247: 45465 | H247: B | I247: SOUTH | J247: BARKADAHAN 2024 | M247: =VLOOKUP(A247,Sheet1!$A$2:$H$1628,1,FALSE) -> 8149-00
A248: 8287-00 | B248: RAZON, JOSE LUIS | C248: 83 | D248: 135 | E248: 72 | F248: 18 | G248: 45487 | H248: B | I248: SOUTH | J248: BARKADAHAN 2024 | M248: =VLOOKUP(A248,Sheet1!$A$2:$H$1628,1,FALSE) -> #N/A
A249: 2781-00 | B249: SARTE, ERNEST | C249: 85 | D249: 135 | E249: 72 | F249: 18 | G249: 45472 | H249: B | I249: SOUTH | J249: BARKADAHAN 2024 | M249: =VLOOKUP(A249,Sheet1!$A$2:$H$1628,1,FALSE) -> 2781-00
...

Sheet orig
A1: account_no | B1: Name | C1: adjusted_gross_score | D1: slope_rating | E1: course_rating | F1: holes_completed | G1: date_played | H1: tee | I1: course | J1: tournament_name | K1: course_id | L1: tee_id | M1: whs_no
A2: 2770-00 | B2: ABAD, RAMON MICHAEL | C2: 97 | D2: 126 | E2: 70.6 | F2: 18 | G2: 45899 | H2: W | I2: SOUTH | J2: All Seniors 2025 | M2: =VLOOKUP(A2,#REF!,5,FALSE) -> #REF!
A3: 2770-00 | B3: ABAD, RAMON MICHAEL | C3: 93 | D3: 125 | E3: 66.7 | F3: 18 | G3: 45914 | H3: W | I3: NORTH | J3: PRESCUP 2025 | M3: =VLOOKUP(A3,#REF!,5,FALSE) -> #REF!
A4: 2770-00 | B4: ABAD, RAMON MICHAEL | C4: 95 | D4: 126 | E4: 70.6 | F4: 18 | G4: 45550 | H4: W | I4: SOUTH | J4: PRESCUP 2024 | M4: =VLOOKUP(A4,#REF!,5,FALSE) -> #REF!
A5: 2770-00 | B5: ABAD, RAMON MICHAEL | C5: 98 | D5: 126 | E5: 70.6 | F5: 18 | G5: 45577 | H5: W | I5: SOUTH | J5: CLUB CHAMP Q1 2025 | M5: =VLOOKUP(A5,#REF!,5,FALSE) -> #REF!
A6: 2770-00 | B6: ABAD, RAMON MICHAEL | C6: 104 | D6: 126 | E6: 70.6 | F6: 18 | G6: 45297 | H6: W | I6: SOUTH | J6: CLUB CHAMP Q1 2024 | M6: =VLOOKUP(A6,#REF!,5,FALSE) -> #REF!
A7: 2770-00 | B7: ABAD, RAMON MICHAEL | C7: 49 | D7: 132 | E7: 36.2 | F7: B9 | G7: 45802 | H7: B | I7: SOUTH | J7: BARKADAHAN 2025 | M7: =VLOOKUP(A7,#REF!,5,FALSE) -> #REF!
A8: 2870-00 | B8: ABALOS, HILARIO O | C8: 76 | D8: 125 | E8: 66.7 | F8: 18 | G8: 45899 | H8: W | I8: NORTH | J8: All Seniors 2025 | M8: =VLOOKUP(A8,#REF!,5,FALSE) -> #REF!
A9: 2870-00 | B9: ABALOS, HILARIO O | C9: 97 | D9: 125 | E9: 66.7 | F9: 18 | G9: 45914 | H9: W | I9: NORTH | J9: PRESCUP 2025 | M9: =VLOOKUP(A9,#REF!,5,FALSE) -> #REF!
A10: 2870-00 | B10: ABALOS, HILARIO O | C10: 82 | D10: 125 | E10: 66.7 | F10: 18 | G10: 45550 | H10: W | I10: NORTH | J10: PRESCUP 2024 | M10: =VLOOKUP(A10,#REF!,5,FALSE) -> #REF!
A11: 2870-00 | B11: ABALOS, HILARIO O | C11: 93 | D11: 126 | E11: 70.6 | F11: 18 | G11: 45774 | H11: W | I11: SOUTH | J11: INTRA 2025 | M11: =VLOOKUP(A11,#REF!,5,FALSE) -> #REF!
A12: 2870-00 | B12: ABALOS, HILARIO O | C12: 100 | D12: 125 | E12: 66.7 | F12: 18 | G12: 45773 | H12: W | I12: NORTH | J12: INTRA 2025 | M12: =VLOOKUP(A12,#REF!,5,FALSE) -> #REF!
A13: 2870-00 | B13: ABALOS, HILARIO O | C13: 81 | D13: 125 | E13: 66.7 | F13: 18 | G13: 45619 | H13: W | I13: NORTH | J13: INTRA 2024 | M13: =VLOOKUP(A13,#REF!,5,FALSE) -> #REF!
A14: 2870-00 | B14: ABALOS, HILARIO O | C14: 99 | D14: 126 | E14: 70.6 | F14: 18 | G14: 45707 | H14: W | I14: SOUTH | J14: DCT 2025 | M14: =VLOOKUP(A14,#REF!,5,FALSE) -> #REF!
A15: 2870-00 | B15: ABALOS, HILARIO O | C15: 99 | D15: 126 | E15: 70.6 | F15: 18 | G15: 45375 | H15: W | I15: SOUTH | J15: DCT 2024 | M15: =VLOOKUP(A15,#REF!,5,FALSE) -> #REF!
A16: 2870-00 | B16: ABALOS, HILARIO O | C16: 91 | D16: 126 | E16: 70.6 | F16: 18 | G16: 45372 | H16: W | I16: SOUTH | J16: DCT 2024 | M16: =VLOOKUP(A16,#REF!,5,FALSE) -> #REF!
A17: 2870-00 | B17: ABALOS, HILARIO O | C17: 95 | D17: 126 | E17: 70.6 | F17: 18 | G17: 45570 | H17: W | I17: SOUTH | J17: CLUB CHAMP Q1 2025 | M17: =VLOOKUP(A17,#REF!,5,FALSE) -> #REF!
A18: 2870-00 | B18: ABALOS, HILARIO O | C18: 94 | D18: 126 | E18: 70.6 | F18: 18 | G18: 45577 | H18: W | I18: SOUTH | J18: CLUB CHAMP Q1 2025 | M18: =VLOOKUP(A18,#REF!,5,FALSE) -> #REF!
A19: 2870-00 | B19: ABALOS, HILARIO O | C19: 91 | D19: 126 | E19: 70.6 | F19: 18 | G19: 45297 | H19: W | I19: SOUTH | J19: CLUB CHAMP Q1 2024 | M19: =VLOOKUP(A19,#REF!,5,FALSE) -> #REF!
... A37: 7851-00 | B37: ADRIANO, JOSE ROBERTO | C37: 85 | D37: 126 | E37: 70.6 | F37: 18 | G37: 45304 | H37: W | I37: SOUTH | J37: CLUB CHAMP Q1 2024 | M37: =VLOOKUP(A37,#REF!,5,FALSE) -> #REF!
A38: 7851-00 | B38: ADRIANO, JOSE ROBERTO | C38: 43 | D38: 128 | E38: 33.8 | F38: F9 | G38: 45808 | H38: W | I38: NORTH | J38: BARKADAHAN 2025 | M38: =VLOOKUP(A38,#REF!,5,FALSE) -> #REF!
A39: 7851-00 | B39: ADRIANO, JOSE ROBERTO | C39: 89 | D39: 126 | E39: 70.6 | F39: 18 | G39: 45899 | H39: W | I39: SOUTH | J39: All Seniors 2025 | M39: =VLOOKUP(A39,#REF!,5,FALSE) -> #REF!
A40: 7073-00 | B40: AFRICA, ALEKHINE C. | C40: 94 | D40: 132 | E40: 68.8 | F40: 18 | G40: 45707 | H40: B | I40: NORTH | J40: DCT 2025 | M40: =VLOOKUP(A40,#REF!,5,FALSE) -> #REF!
A41: 7073-00 | B41: AFRICA, ALEKHINE C. | C41: 100 | D41: 134 | E41: 72.8 | F41: 18 | G41: 45710 | H41: B | I41: SOUTH | J41: DCT 2025 | M41: =VLOOKUP(A41,#REF!,5,FALSE) -> #REF!
A42: 8511-00 | B42: AGUAS, MARIE SIMONETTE | C42: 117 | D42: 129 | E42: 73.3 | F42: 18 | G42: 45914 | H42: R | I42: SOUTH | J42: PRESCUP 2025 | M42: =VLOOKUP(A42,#REF!,5,FALSE) -> #REF!
A43: 8135-00 | B43: AGUILA, ROMULO JR. | C43: 94 | D43: 125 | E43: 66.7 | F43: 18 | G43: 45619 | H43: W | I43: NORTH | J43: INTRA 2024 | M43: =VLOOKUP(A43,#REF!,5,FALSE) -> #REF!
A44: 2767-00 | B44: AGUILAR, ADOLFO JR B. | C44: 89 | D44: 134 | E44: 72.8 | F44: 18 | G44: 45550 | H44: B | I44: SOUTH | J44: PRESCUP 2024 | M44: =VLOOKUP(A44,#REF!,5,FALSE) -> #REF!
A45: 2767-00 | B45: AGUILAR, ADOLFO JR B. | C45: 92 | D45: 134 | E45: 72.8 | F45: 18 | G45: 45577 | H45: B | I45: SOUTH | J45: CLUB CHAMP Q1 2025 | M45: =VLOOKUP(A45,#REF!,5,FALSE) -> #REF!
A46: 2767-00 | B46: AGUILAR, ADOLFO JR B. | C46: 91 | D46: 134 | E46: 72.8 | F46: 18 | G46: 45297 | H46: B | I46: SOUTH | J46: CLUB CHAMP Q1 2024 | M46: =VLOOKUP(A46,#REF!,5,FALSE) -> #REF!
A47: 2767-00 | B47: AGUILAR, ADOLFO JR. | C47: 91 | D47: 134 | E47: 72.8 | F47: 18 | G47: 45914 | H47: B | I47: SOUTH | J47: PRESCUP 2025 | M47: =VLOOKUP(A47,#REF!,5,FALSE) -> #REF!
A48: 8528-00 | B48: AGUILAR, ANDRE PAOLO A. | C48: 85 | D48: 134 | E48: 72.8 | F48: 18 | G48: 45577 | H48: B | I48: SOUTH | J48: CLUB CHAMP Q1 2025 | M48: =VLOOKUP(A48,#REF!,5,FALSE) -> #REF!
A49: 8528-00 | B49: AGUILAR, ANDRE PAOLO A. | C49: 91 | D49: 134 | E49: 72.8 | F49: 18 | G49: 45570 | H49: B | I49: SOUTH | J49: CLUB CHAMP Q1 2025 | M49: =VLOOKUP(A49,#REF!,5,FALSE) -> #REF!
A50: 3309-00 | B50: AGUILAR, FRANCIS | C50: 109 | D50: 134 | E50: 72.8 | F50: 18 | G50: 45914 | H50: B | I50: SOUTH | J50: PRESCUP 2025 | M50: =VLOOKUP(A50,#REF!,5,FALSE) -> #REF!
... A67: 7776-00 | B67: ALBA, JASON J | C67: 102 | D67: 134 | E67: 72.8 | F67: 18 | G67: 45304 | H67: B | I67: SOUTH | J67: CLUB CHAMP Q1 2024 | M67: =VLOOKUP(A67,#REF!,5,FALSE) -> #REF!
A68: 3551-00 | B68: ALCANTARA, MARCELINO III CRISOSTOMO | C68: 50 | D68: 136 | E68: 36.6 | F68: F9 | G68: 45837 | H68: B | I68: SOUTH | J68: BARKADAHAN 2025 | M68: =VLOOKUP(A68,#REF!,5,FALSE) -> #REF!
A69: 3374-00 | B69: ALCANTARA, MARCELINO "MENCY" | C69: 89 | D69: 125 | E69: 66.7 | F69: 18 | G69: 45899 | H69: W | I69: NORTH | J69: All Seniors 2025 | M69: =VLOOKUP(A69,#REF!,5,FALSE) -> #REF!
A70: 3374-00 | B70: ALCANTARA, MARCELINO "MENCY" | C70: 0 | D70: 125 | E70: 66.7 | F70: 18 | G70: 45914 | H70: W | I70: NORTH | J70: PRESCUP 2025 | M70: =VLOOKUP(A70,#REF!,5,FALSE) -> #REF!
A71: 3551-00 | B71: ALCANTARA, MARCELINO III CRISOSTOMO | C71: 90 | D71: 134 | E71: 72.8 | F71: 18 | G71: 45774 | H71: B | I71: SOUTH | J71: INTRA 2025 | M71: =VLOOKUP(A71,#REF!,5,FALSE) -> #REF!
A72: 3551-00 | B72: ALCANTARA, MARCELINO III CRISOSTOMO | C72: 104 | D72: 132 | E72: 68.8 | F72: 18 | G72: 45773 | H72: B | I72: NORTH | J72: INTRA 2025 | M72: =VLOOKUP(A72,#REF!,5,FALSE) -> #REF!
A73: 7915-00 | B73: ALCANTARA, RODOLFO | C73: 102 | D73: 125 | E73: 66.7 | F73: 18 | G73: 45619 | H73: W | I73: NORTH | J73: INTRA 2024 | M73: =VLOOKUP(A73,#REF!,5,FALSE) -> #REF!
...

Sheet Sheet3

Sheet Sheet4
A1: account_no | B1: Name | C1: course_id | D1: tee_id | E1: whs_no
A2: 8511-00 | B2: AGUAS, MARIE SIMONETTE | E2: 1001820 | F2: WACK
A3: 2767-00 | B3: AGUILAR, ADOLFO JR B. | E3: 34680
A4: 3551-00 | B4: ALCANTARA, MARCELINO III CRISOSTOMO | E4: 10704
A5: 7943-00 | B5: ALINO, CARLO EDUARDO | E5: 41643
A6: 3585-03 | B6: ALMAZAN, BASILIO ISAAC | E6: 71919 | F6: FH
A7: 3585-00 | B7: ALMAZAN, BASILIO JR. | E7: 29274 | F7: FH
A8: 3585-02 | B8: ALMAZAN, EARL EDUARD | E8: 71918
A9: 7471-00 | B9: ALMEDA, RENE T. | E9: 6090
A10: 3039-00 | B10: AN, YOUNG JAE | E10: 77412
A11: 3081-00 | B11: ANG, RANDY | E11: -
A12: 2146-00 | B12: ANONAS , GERARDO B. | E12: 8651
A13: 8199-00 | B13: AQUINO, ALEX | E13: -
A14: 8008-00 | B14: ATAYDE, THERESA REMEDIOS "RIZZA" T | E14: 49360
A15: 8264-00 | B15: ATENCIO, JANUARIO JESUS | E15: 70912
A16: 2480-00 | B16: AVILA, ROMEO M. | E16: 12563
A17: 3002-00 | B17: BARCELON, JOSE ANCHETA | E17: 68282
A18: 8289-00 | B18: BARRETTO, DON RYAN | E18: 73145
A19: 3577-00 | B19: BAYHON, VINCENT PATRICK | E19: 72313
A20: 2614-00 | B20: BENITEZ, TOMAS JULIO A. | E20: 8750
A21: 8398-00 | B21: BERNAS, JORGE ALEXANDER | E21: 21647
A22: 8569-00 | B22: BONGAT, JEFFERSON | E22: 1000963
A23: 8218-00 | B23: BONGAT, NOEL | E23: 12607
A24: 3350-00 | B24: BULUT, ELIAS JR. | E24: 78245
A25: 3004-00 | B25: CABANELA, RICH- O | E25: 36080
... A27: 8449-00 | B27: CAGALINGAN, JOSE PAOLO | E27: 65740
A28: 8309-00 | B28: CALDERON, CHRIS ALLEN | E28: #N/A
A29: 8145-00 | B29: CAPARROS, IRENE MARGOT | E29: 26936
A30: 1058-00 | B30: CAPARROS, MARVIN A. | E30: 412
A31: 1058-01 | B31: CAPARROS, MILDRED MYRA | E31: 26938
A32: 187-01 | B32: CARLOS, ARSENIA | E32: 8815
A33: 187-00 | B33: CARLOS, ARTHUR | E33: 8816
A34: 7676-03 | B34: CARPESO, ZHAQUILL ELDON | E34: 17924
A35: 686-00 | B35: CARPIO, CARLO | E35: 8825
A36: 686-01 | B36: CARPIO, SYLVIA | E36: 8826
A37: 3482-00 | B37: CERENO, CONRAD | E37: 67681
A38: 3541-02 | B38: CHAM, ETHAN ALEXANDER | E38: 10004377
A39: 8203-03 | B39: CHAN, AERIN | E39: 78119
A40: 8203-01 | B40: CHAN, JEFFREI | E40: 73954
... A42: 8059-00 | B42: CHENG, ANTHONY | E42: 26964
...

Sheet Sheet1 (2)
A1: account_no | B1: last_name | C1: first_name | D1: middle_name | E1: whs_no | F1: BIRTHDAY | G1: sex | H1: NAME | J1: account_no | K1: last_name | L1: first_name | M1: middle_name | N1: whs_no | O1: BIRTHDAY | P1: sex | Q1: EMAIL | R1: NAME
A2: 0015-00 | B2: PUYAT | C2: RAYMUND | E2: 9724 | F2: 23378 | G2: M | H2: PUYAT, RAYMUND | J2: 0015-00 | K2: PUYAT | L2: RAYMUND | N2: 9724 | O2: 23378 | P2: M | Q2: rbpuyat@gmail.com | R2: PUYAT, RAYMUND
A3: 0017-00 | B3: CRUZ | C3: JOSE "PINGGOY" | E3: 8933 | F3: 14278 | G3: M | H3: CRUZ, JOSE "PINGGOY" | J3: 0017-00 | K3: CRUZ | L3: JOSE "PINGGOY" | N3: 8933 | O3: 14278 | P3: M | Q3: hebhighendbroadcast@gmail.com | R3: CRUZ, JOSE "PINGGOY"
A4: 0021-00 | B4: MESINA | C4: JACINTO "JESS" | E4: 9539 | F4: 13804 | G4: M | H4: MESINA, JACINTO "JESS" | J4: 0021-00 | K4: MESINA | L4: JACINTO "JESS" | N4: 9539 | O4: 13804 | P4: M | Q4: jessmesina16@gmail.com | R4: MESINA, JACINTO "JESS"
A5: 0033-00 | B5: GO | C5: EDGARDO "EDDIE" | E5: 9178 | F5: 20824 | G5: M | H5: GO, EDGARDO "EDDIE" | J5: 0033-00 | K5: GO | L5: EDGARDO "EDDIE" | N5: 9178 | O5: 20824 | P5: M | Q5: gts_center@yahoo.com | R5: GO, EDGARDO "EDDIE"
A6: 0034-00 | B6: LOPEZ | C6: INOCENCIO "ENNIE" | E6: 9451 | F6: 18448 | G6: M | H6: LOPEZ, INOCENCIO "ENNIE" | J6: 0034-00 | K6: LOPEZ | L6: INOCENCIO "ENNIE" | N6: 9451 | O6: 18448 | P6: M | Q6: lopezinocencio692@gmail.com | R6: LOPEZ, INOCENCIO "ENNIE"
A7: 0053-00 | B7: CAPISTRANO | C7: EDMUNDO "JUN" | E7: 8809 | F7: 18375 | G7: M | H7: CAPISTRANO, EDMUNDO "JUN" | J7: 0053-00 | K7: CAPISTRANO | L7: EDMUNDO "JUN" | N7: 8809 | O7: 18375 | P7: M | Q7: capistrano911@yahoo.com | R7: CAPISTRANO, EDMUNDO "JUN"
A8: 0058-00 | B8: ALVENDIA | C8: ROLANDO | E8: 8640 | F8: 19520 | G8: M | H8: ALVENDIA, ROLANDO | J8: 0058-00 | K8: ALVENDIA | L8: ROLANDO | N8: 8640 | O8: 19520 | P8: M | Q8: rmalvendia2005@yahoo.com | R8: ALVENDIA, ROLANDO
A9: 0076-00 | B9: LAZO | C9: SAMSON "SAMMY" | E9: 9359 | F9: 16279 | G9: M | H9: LAZO, SAMSON "SAMMY" | J9: 0076-00 | K9: LAZO | L9: SAMSON "SAMMY" | N9: 9359 | O9: 16279 | P9: M | Q9: sammylazo@yahoo.com | R9: LAZO, SAMSON "SAMMY"
A10: 0081-00 | B10: LITTAUA | C10: DIONISIO "DIONNY" | E10: 9433 | F10: 22664 | G10: M | H10: LITTAUA, DIONISIO "DIONNY" | J10: 0081-00 | K10: LITTAUA | L10: DIONISIO "DIONNY" | N10: 9433 | O10: 22664 | P10: M | Q10: littcon@gmail.com | R10: LITTAUA, DIONISIO "DIONNY"
A11: 0081-01 | B11: LITTAUA | C11: MA TERESA | E11: 9434 | F11: 24231 | G11: F | H11: LITTAUA, MA TERESA | J11: 0081-01 | K11: LITTAUA | L11: MA TERESA | N11: 9434 | O11: 24231 | P11: F | R11: LITTAUA, MA TERESA
A12: 0094-00 | B12: STROEM | C12: LEA ANA | E12: 9958 | F12: 21976 | G12: F | H12: STROEM, LEA ANA | J12: 0094-00 | K12: STROEM | L12: LEA ANA | N12: 9958 | O12: 21976 | P12: F | Q12: leastroem@yahoo.com | R12: STROEM, LEA ANA
A13: 0094-01 | B13: STROEM | C13: RUNE | E13: 75420 | F13: 22695 | G13: M | H13: STROEM, RUNE | J13: 0094-01 | K13: STROEM | L13: RUNE | N13: 75420 | O13: 22695 | P13: M | Q13: stroemrune@gmail.com | R13: STROEM, RUNE
A14: 0109-00 | B14: SO | C14: WILSON | E14: 75039 | F14: 18840 | G14: M | H14: SO, WILSON | J14: 0109-00 | K14: SO | L14: WILSON | N14: 75039 | O14: 18840 | P14: M | Q14: wilson@toneguide.com.ph | R14: SO, WILSON
A15: 0121-00 | B15: PEGELS | C15: VIOLETA "VIOLY" | E15: 9693 | F15: 20881 | G15: F | H15: PEGELS, VIOLETA "VIOLY" | J15: 0121-00 | K15: PEGELS | L15: VIOLETA "VIOLY" | N15: 9693 | O15: 20881 | P15: F | Q15: violypegels@rocketmail.com | R15: PEGELS, VIOLETA "VIOLY"
A16: 0122-00 | B16: ONG | C16: JOSELITO "JOJO" | E16: 9613 | F16: 19884 | G16: M | H16: ONG, JOSELITO "JOJO" | J16: 0122-00 | K16: ONG | L16: JOSELITO "JOJO" | N16: 9613 | O16: 19884 | P16: M | Q16: joselitodong@gmail.com | R16: ONG, JOSELITO "JOJO"
A17: 0123-00 | B17: GO | C17: MARCELINO "DAUDO" | E17: 9184 | F17: 18359 | G17: M | H17: GO, MARCELINO "DAUDO" | J17: 0123-00 | K17: GO | L17: MARCELINO "DAUDO" | N17: 9184 | O17: 18359 | P17: M | Q17: daudogo@gmail.com | R17: GO, MARCELINO "DAUDO"
A18: 0131-00 | B18: UY | C18: SAMUEL | E18: 10072 | F18: 22890 | G18: M | H18: UY, SAMUEL | J18: 0131-00 | K18: UY | L18: SAMUEL | N18: 10072 | O18: 22890 | P18: M | Q18: jenny_uy63@yahoo.com | R18: UY, SAMUEL
A19: 0137-00 | B19: SAN AGUSTIN | C19: ARISTEO "ARIS" | E19: 9843 | F19: 17874 | G19: M | H19: SAN AGUSTIN, ARISTEO "ARIS" | J19: 0137-00 | K19: SAN AGUSTIN | L19: ARISTEO "ARIS" | N19: 9843 | O19: 17874 | P19: M | Q19: asa747@hotmail.com | R19: SAN AGUSTIN, ARISTEO "ARIS"
A20: 0139-00 | B20: ABAYA | C20: RODOLFO | E20: 8593 | F20: 22943 | G20: M | H20: ABAYA, RODOLFO | J20: 0139-00 | K20: ABAYA | L20: RODOLFO | N20: 8593 | O20: 22943 | P20: M | Q20: roddyabaya@mac.com | R20: ABAYA, RODOLFO
A21: 0144-00 | B21: REVERENTE JR | C21: BENITO | E21: 9771 | F21: 11698 | G21: M | H21: REVERENTE JR, BENITO | J21: 0144-00 | K21: REVERENTE JR | L21: BENITO | N21: 9771 | O21: 11698 | P21: M | R21: REVERENTE JR, BENITO
A22: 0164-00 | B22: VILCHEZ JR | C22: JOSE "BONG" | E22: 20796 | F22: 19196 | G22: M | H22: VILCHEZ JR, JOSE "BONG" | J22: 0164-00 | K22: VILCHEZ JR | L22: JOSE "BONG" | N22: 20796 | O22: 19196 | P22: M | Q22: jrvilchez27@gmail.com | R22: VILCHEZ JR, JOSE "BONG"
A23: 0172-00 | B23: VELAYO JR | C23: JACINTO | E23: 10084 | F23: 23304 | G23: M | H23: VELAYO JR, JACINTO | J23: 0172-00 | K23: VELAYO JR | L23: JACINTO | N23: 10084 | O23: 23304 | P23: M | Q23: jun.velayo54@gmail.com | R23: VELAYO JR, JACINTO
A24: 0174-00 | B24: CASA | C24: ORLANDO "ORLY" | E24: 15719 | F24: 24902 | G24: M | H24: CASA, ORLANDO "ORLY" | J24: 0174-00 | K24: CASA | L24: ORLANDO "ORLY" | N24: 15719 | O24: 24902 | P24: M | Q24: orlsc@yahoo.com | R24: CASA, ORLANDO "ORLY"
A25: 0187-00 | B25: CARLOS | C25: ARTHUR "ART" | E25: 8816 | F25: 19723 | G25: M | H25: CARLOS, ARTHUR "ART" | J25: 0187-00 | K25: CARLOS | L25: ARTHUR "ART" | N25: 8816 | O25: 19723 | P25: M | Q25: art_constech@yahoo.com | R25: CARLOS, ARTHUR "ART"
A26: 0187-01 | B26: CARLOS | C26: ARSENIA "ZENY" | E26: 8815 | F26: 20369 | G26: F | H26: CARLOS, ARSENIA "ZENY" | J26: 0187-01 | K26: CARLOS | L26: ARSENIA "ZENY" | N26: 8815 | O26: 20369 | P26: F | Q26: zehn_constech@yahoo.com.ph | R26: CARLOS, ARSENIA "ZENY"
A27: 0207-00 | B27: BAUTISTA | C27: ALFREDO "FREDDIE" | E27: 8739 | F27: 21868 | G27: M | H27: BAUTISTA, ALFREDO "FREDDIE" | J27: 0207-00 | K27: BAUTISTA | L27: ALFREDO "FREDDIE" | N27: 8739 | O27: 21868 | P27: M | Q27: alfjbautista@gmail.com | R27: BAUTISTA, ALFREDO "FREDDIE"
A28: 0215-00 | B28: VIDANES | C28: D. PAULO | E28: 10094 | F28: 23188 | G28: M | H28: VIDANES, D. PAULO | J28: 0215-00 | K28: VIDANES | L28: D. PAULO | N28: 10094 | O28: 23188 | P28: M | Q28: paulvidanes@gmail.com | R28: VIDANES, D. PAULO
A29: 0220-00 | B29: DE LEON JR | C29: INOCENCIO | E29: 8970 | F29: 14298 | G29: M | H29: DE LEON JR, INOCENCIO | J29: 0220-00 | K29: DE LEON JR | L29: INOCENCIO | N29: 8970 | O29: 14298 | P29: M | Q29: de_leon1939@yahoo.com | R29: DE LEON JR, INOCENCIO
A30: 0225-00 | B30: DELA CRUZ | C30: BENITO "BENNY" | E30: 8991 | F30: 17011 | G30: M | H30: DELA CRUZ, BENITO "BENNY" | J30: 0225-00 | K30: DELA CRUZ | L30: BENITO "BENNY" | N30: 8991 | O30: 17011 | P30: M | Q30: bentcz@yahoo.com | R30: DELA CRUZ, BENITO "BENNY"
A31: 0242-00 | B31: VILLALUNA JR. | C31: JOSE | E31: 10103 | F31: 14658 | G31: M | H31: VILLALUNA JR., JOSE | J31: 0242-00 | K31: VILLALUNA JR. | L31: JOSE | N31: 10103 | O31: 14658 | P31: M | Q31: jecvpxm@yahoo.com.ph | R31: VILLALUNA JR., JOSE
A32: 0262-00 | B32: MENDOZA | C32: HONOR S. | E32: 9531 | F32: 22914 | G32: M | H32: MENDOZA, HONOR S. | J32: 0262-00 | K32: MENDOZA | L32: HONOR S. | N32: 9531 | O32: 22914 | P32: M | Q32: hsm7775@yahoo.com | R32: MENDOZA, HONOR S.
A33: 0275-00 | B33: ESGUERRA | C33: CECILE | E33: 9065 | F33: 22669 | G33: F | H33: ESGUERRA, CECILE | J33: 0275-00 | K33: ESGUERRA | L33: CECILE | N33: 9065 | O33: 22669 | P33: F | Q33: cjnesguerra@yahoo.com | R33: ESGUERRA, CECILE
... A39: 0306-00 | B39: TANCHI JR | C39: ERNESTO | E39: 10011 | F39: 17320 | G39: M | H39: TANCHI JR, ERNESTO | J39: 0306-00 | K39: TANCHI JR | L39: ERNESTO | N39: 10011 | O39: 17320 | P39: M | Q39: ernietanchi@yahoo.com | R39: TANCHI JR, ERNESTO
A40: 0307-00 | B40: SUMULONG | C40: LORENZO | E40: 70138 | F40: 2075 | G40: M | H40: SUMULONG, LORENZO | J40: 0307-00 | K40: SUMULONG | L40: LORENZO | N40: 70138 | O40: 2075 | P40: M | R40: SUMULONG, LORENZO
A41: 0333-00 | B41: HUANG | C41: PING | E41: 76905 | F41: 15600 | G41: M | H41: HUANG, PING | J41: 0333-00 | K41: HUANG | L41: PING | N41: 76905 | O41: 15600 | P41: M | R41: HUANG, PING
A42: 0358-00 | B42: TUASON | C42: ELIZABETH | E42: 76445 | F42: 13518 | G42: F | H42: TUASON, ELIZABETH | J42: 0358-00 | K42: TUASON | L42: ELIZABETH | N42: 76445 | O42: 13518 | P42: F | R42: TUASON, ELIZABETH
A43: 0362-00 | B43: UNLAY | C43: RAYMOND PETER "PETE" | E43: 22311 | F43: 25180 | G43: M | H43: UNLAY, RAYMOND PETER "PETE" | J43: 0362-00 | K43: UNLAY | L43: RAYMOND PETER "PETE" | N43: 22311 | O43: 25180 | P43: M | Q43: peter.unlay@yahoo.com | R43: UNLAY, RAYMOND PETER "PETE"
A44: 0368-00 | B44: DE UBAGO | C44: ANTONIO | E44: 21767 | F44: 17852 | G44: M | H44: DE UBAGO, ANTONIO | J44: 0368-00 | K44: DE UBAGO | L44: ANTONIO | N44: 21767 | O44: 17852 | P44: M | Q44: tonydeu131@gmail.com | R44: DE UBAGO, ANTONIO
A45: 0380-00 | B45: CORONEL | C45: JOEL NAPOLEON | E45: 8910 | F45: 21438 | G45: M | H45: CORONEL, JOEL NAPOLEON | J45: 0380-00 | K45: CORONEL | L45: JOEL NAPOLEON | N45: 8910 | O45: 21438 | P45: M | Q45: arthur_coronel@yahoo.com | R45: CORONEL, JOEL NAPOLEON
...

Sheet Sheet1
A1: account_no | B1: last_name | C1: first_name | D1: middle_name | E1: whs_no | F1: BIRTHDAY | G1: sex | H1: EMAIL
A2: 0081-01 | B2: LITTAUA | C2: MA TERESA | E2: 9434 | F2: 24231 | G2: F
A3: 0144-00 | B3: REVERENTE JR | C3: BENITO | E3: 9771 | F3: 11698 | G3: M
A4: 0307-00 | B4: SUMULONG | C4: LORENZO | E4: 70138 | F4: 2075 | G4: M
A5: 0333-00 | B5: HUANG | C5: PING | E5: 76905 | F5: 15600 | G5: M
A6: 0358-00 | B6: TUASON | C6: ELIZABETH | E6: 76445 | F6: 13518 | G6: F
A7: 0510-00 | B7: LANUZA JR | C7: CAESAR "JUN" | E7: 21137 | F7: 16984 | G7: M
A8: 0530-00 | B8: CONSOLACION | C8: THOMAS "TOM" | E8: 8905 | F8: 18751 | G8: M
A9: 0665-01 | B9: NARCELLES | C9: MYRNA | E9: 9568 | F9: 16971 | G9: F
A10: 0929-01 | B10: CABANGBANG | C10: CLARITA | E10: 10335 | F10: 22244 | G10: F
A11: 1234-02 | B11: CASTAÑEDA | C11: JOSE MIGUEL "MAIO" | E11: 10769 | F11: 37906 | G11: M
A12: 1501-00 | B12: SILVA | C12: DINA | E12: 9932 | F12: 13619 | G12: F
A13: 2097-00 | B13: CU UNJIENG | C13: ROMAN | E13: 8940 | F13: 25477 | G13: M
... A17: 2367-00 | B17: ONGKIKO | C17: SONIA | E17: 9622 | F17: 12318 | G17: F
A18: 2530-06 | B18: ZHANG | C18: ABIGAIL | F18: 37974 | G18: F
A19: 2599-04 | B19: GREGORE | C19: ANGELICA NOUELLE | E19: 75651 | F19: 36924 | G19: F
A20: 2654-00 | B20: ROBLES | C20: DANILO | E20: 9799 | F20: 22480 | G20: M
A21: 2673-00 | B21: JARANTILLA JR | C21: FEDERICO | E21: 9275 | F21: 13676 | G21: M
A22: 2709-00 | B22: TAN | C22: EDWIN | E22: 10718 | F22: 20827 | G22: M
A23: 2718-00 | B23: ROLDAN | C23: JAMES | E23: 10303 | F23: 24479 | G23: M
A24: 2733-00 | B24: BAKUNAWA | C24: MANUEL "BUTCH" R. | E24: 10273 | F24: 31766 | G24: M
A25: 2776-00 | B25: APUHIN | C25: EVANGELINE "VANGIE" | E25: 8656 | F25: 23302 | G25: F
A26: 2824-00 | B26: KUBO | C26: ATSUSHI | E26: 44804 | F26: 26442 | G26: M
A27: 3076-03 | B27: BORROMEO | C27: MARIA MONICA | E27: 77565 | F27: 35189 | G27: F
A28: 3118-02 | B28: SEE | C28: DAMIEN MARCUS | E28: 49922 | F28: 38101 | G28: M
A29: 3219-02 | B29: ESCALADA | C29: EMMANUELLE | E29: 68879 | F29: 38407 | G29: F
A30: 3221-01 | B30: LAUREL | C30: JOSE ARSENIO | E30: 21142 | F30: 32483 | G30: M
... A36: 3511-03 | B36: CO | C36: RAPHAEL DAVID | E36: 1009246 | F36: 40386 | G36: M
A37: 3511-04 | B37: CO | C37: ARIANA | F37: 41878 | G37: F
A38: 3513-00 | B38: YANG | C38: HONG MING | E38: 77230 | F38: 28035 | G38: M
A39: 3514-03 | B39: CRUZ | C39: JUAN ANTONIO ''JUANTON'' P | E39: 77076 | F39: 41115 | G39: M
A40: 3574-00 | B40: SEE | C40: ROBIN | E40: 1002727 | F40: 37681 | G40: M
A41: 3637-04 | B41: CHUA | C41: JOHN | E41: 1008942 | F41: 41038 | G41: M
A42: 3696-02 | B42: GUICO | C42: MIGUEL KRISTOFF | E42: 1001291 | F42: 40092 | G42: M
A43: 7116-00 | B43: MENDOZA | C43: NESTOR "JAY" | E43: 41034 | F43: 41622 | G43: M
A44: 7493-02 | B44: PABLICO | C44: LUIGI BRIAN | E44: 14867 | F44: 33312 | G44: M
A45: 7508-01 | B45: LEGARDA | C45: JENNIFER | E45: 10201 | F45: 24582 | G45: F
A46: 7957-03 | B46: LEE | C46: CIAN STEPHEN | E46: 71466 | F46: 38299 | G46: M
A47: 8054-03 | B47: DE GUZMAN | C47: EMMANUEL "MANOLO" | E47: 75896 | F47: 38535 | G47: M
A48: 8062-00 | B48: UNTALAN | C48: MYLA | E48: 66488 | F48: 25799 | G48: F
...

Sheet EMAIL
A1: ACCTNO | B1: NAME | C1: EMAIL
A2: 2585-00 | B2: BENG CHEONG TAY | C2: petertay29@gmail.com
A3: 2688-02 | B3: ERIC JOHN ILLESCAS | C3: 268802@noemail.com
A4: 8487-01 | B4: MANUEL RAVAGO | C4: mjravago@outlook.com
A5: 8453-02 | B5: KEIRA IZABELLE S. LIM | C5: keira@noemail.com
A6: 8194-02 | B6: TAMARA JORGE | C6: jorge.tamara@gmail.com
A7: 3466-00 | B7: WILLIAM LESTER KHO | C7: williamkho1@yahoo.com
A8: 0138-00 | B8: JAIME LIM SE CHUN | C8: jaimesclim@hotmail.com
A9: 8495-00 | B9: JOHANN LESTER SY | C9: johannsy1998@gmail.com
A10: 3417-00 | B10: VICTORIO EMMANUEL DIONISIO | C10: dinomdionisio@gmail.com
A11: 8285-00 | B11: MIGUEL B. MORADA JR. | C11: mmjr100@icloud.com
A12: 3459-01 | B12: ARLENE ANG | C12: arlene@conmaster.com.ph
... A3322: 7042-04 | B3322: VITTO MIRAVITE | C3322: vittomiravite96@gmail.com
